Workbook

Sheet Assumptions
A1: INVERTA — monthly infrastructure cost model
A2: Blue cells are inputs. Yellow cells are the ones to verify before trusting the total — they are either third-party rates I could not confirm, or figures only you know.
A4: CONTENT & AUDIENCE
A5: Lessons in the program | B5: 20 | C5: Video sessions with a recording.
A6: Average lesson length (minutes) | B6: 15
A7: Total content (minutes) | B7: =B5*B6
A8: Students per month | B8: 30 | C8: Active cohort.
A9: Rewatch factor | B9: 1.3 | C9: 1.0 = watches everything once. 1.3 assumes 30% revisiting.
A10: Minutes delivered per month | B10: =B7*B8*B9
A12: VIDEO ENCODING
A13: Delivered size (MB per minute) | B13: 5 | C13: Screencast at ~650 kbps. Measure a real export and replace this.
A14: Storage ladder multiplier | B14: 2.5 | C14: Bunny keeps several renditions per source.
A15: GB delivered per month | B15: =B10*B13/1024
A16: GB stored (video) | B16: =B7*B13*B14/1024 | C16: Grows as you add lessons; not per-month.
A18: BUNNY STREAM RATES — VERIFY
A19: Storage ($/GB/month) | B19: 0.01
A20: Delivery ($/GB, Asia & Oceania) | B20: 0.03 | C20: Higher than EU/NA. Most likely figure to be wrong.
A21: Minimum monthly charge ($) | B21: 1 | C21: Bunny applies a monthly floor.
A23: SERVER — MAC MINI (self-hosted)
A24: Hardware purchase price (IDR) | B24: 12000000 | C24: Leave as-is if already owned; it still has an opportunity cost.
A25: Amortisation period (months) | B25: 36 | C25: Set to a very large number to treat the hardware as free.
A26: Hardware per month (IDR) | B26: =IF(B25=0,0,B24/B25)
A27: Average power draw (watts) | B27: 15 | C27: Apple silicon Mac mini idles low; this app is not CPU-heavy.
A28: Electricity tariff (IDR per kWh) | B28: 1700 | C28: PLN household tariff — check your actual band.
A29: Electricity per month (IDR) | B29: =B27*24*30/1000*B28
A30: Internet subscription (IDR/month) | B30: 500000 | C30: Your existing home/office fibre.
A31: Share attributed to this app | B31: 0.3 | C31: You would pay for the line anyway; charge the app only its share.
A32: Internet per month (IDR) | B32: =B30*B31
A34: CLOUDFLARE
A35: Tunnel (IDR/month) | B35: 0 | C35: Cloudflare Tunnel is free.
A36: R2 audio stored (GB) | B36: 1.5 | C36: Listening recordings. Grows with the question bank.
A37: R2 free storage tier (GB) | B37: 10
A38: R2 storage ($/GB/month) | B38: 0.015 | C38: Egress is $0 — that is R2's whole point.
A39: R2 cost ($/month) | B39: =MAX(0,B36-B37)*B38
A41: EMAIL — AMAZON SES
A42: Emails per student per month | B42: 10 | C42: Verification, receipt, certificate, reminders.
A43: SES rate ($ per 1,000 emails) | B43: 0.1
A44: SES cost ($/month) | B44: =B8*B42/1000*B43
A46: PAYMENTS — the line item that actually scales
A47: Program price (IDR) | B47: 1500000 | C47: KAK section 17 item 5 — still a placeholder.
...

Sheet Monthly Cost
A1: Monthly cost — all services
A2: Every figure is a formula off Assumptions. Change an input there and this updates.
A4: Line item | B4: Basis | C4: Cost (USD) | D4: Cost (IDR) | E4: % of total
A5: Bunny Stream — video | B5: Storage + delivery, min charge applied | C5: =MAX('Assumptions'!B16*'Assumptions'!B19+'Assumptions'!B15*'Assumptions'!B20,'Assumptions'!B21) | D5: =C5*'Assumptions'!$B$58 | E5: =IF($D$15=0,0,D5/$D$15)
A6: Cloudflare R2 — audio | B6: Storage above free tier; egress free | C6: ='Assumptions'!B39 | D6: =C6*'Assumptions'!$B$58 | E6: =IF($D$15=0,0,D6/$D$15)
A7: Cloudflare Tunnel | B7: Free tier | C7: =D7/'Assumptions'!$B$58 | D7: ='Assumptions'!B35 | E7: =IF($D$15=0,0,D7/$D$15)
A8: Amazon SES — email | B8: Per 1,000 emails | C8: ='Assumptions'!B44 | D8: =C8*'Assumptions'!$B$58 | E8: =IF($D$15=0,0,D8/$D$15)
A9: Mac mini — hardware | B9: Purchase price amortised | C9: =D9/'Assumptions'!$B$58 | D9: ='Assumptions'!B26 | E9: =IF($D$15=0,0,D9/$D$15)
A10: Mac mini — electricity | B10: Watts x 24h x 30d x tariff | C10: =D10/'Assumptions'!$B$58 | D10: ='Assumptions'!B29 | E10: =IF($D$15=0,0,D10/$D$15)
A11: Internet — attributed share | B11: Subscription x share | C11: =D11/'Assumptions'!$B$58 | D11: ='Assumptions'!B32 | E11: =IF($D$15=0,0,D11/$D$15)
A12: Domain | B12: Annual / 12 | C12: =D12/'Assumptions'!$B$58 | D12: ='Assumptions'!B55 | E12: =IF($D$15=0,0,D12/$D$15)
A13: Payment gateway | B13: % of revenue + per-transaction | C13: =D13/'Assumptions'!$B$58 | D13: ='Assumptions'!B51 | E13: =IF($D$15=0,0,D13/$D$15)
A15: TOTAL | C15: =SUM(C5:C13) | D15: =SUM(D5:D13) | E15: =IF($D$15=0,0,SUM(E5:E13))
A18: Against revenue
A19: Revenue per month | D19: ='Assumptions'!B48
A20: Infrastructure as % of revenue | D20: =IF('Assumptions'!B48=0,0,D15/'Assumptions'!B48)
A21: Infrastructure cost per student | D21: =IF('Assumptions'!B8=0,0,D15/'Assumptions'!B8)
A22: Excluding payment fees, per student | D22: =IF('Assumptions'!B8=0,0,(D15-D13)/'Assumptions'!B8)
A25: Not included — and one of these dwarfs everything above
A26: - Producing the videos: recording, editing, and the person doing it. This is your real cost centre, not hosting.
A27: - Writing the question bank — 140 final items plus gating tests (KAK section 17 item 4).
A28: - Your own time, or anyone you pay to run the programme.
A29: - Backups. Budget a little R2 storage for Postgres dumps; a self-hosted database with no offsite backup is a single disk failure from losing every learner record.
A30: - Taxes on revenue, and any legal review of the TOEFL naming (KAK section 17 item 2).

Sheet Sensitivity
A1: Cost by cohort size
A2: Only the student count varies. Fixed costs stay flat; Bunny and the gateway scale.
A4: Students/month | B4: Bunny (IDR) | C4: Gateway (IDR) | D4: Other fixed (IDR) | E4: TOTAL (IDR/mo) | F4: Revenue (IDR/mo) | G4: Infra % of revenue
A5: 10 | B5: =MAX('Assumptions'!$B$16*'Assumptions'!$B$19+A5*'Assumptions'!$B$7*'Assumptions'!$B$9*'Assumptions'!$B$13/1024*'Assumptions'!$B$20,'Assumptions'!$B$21)*'Assumptions'!$B$58 | C5: =A5*'Assumptions'!$B$47*'Assumptions'!$B$49+A5*'Assumptions'!$B$50 | D5: ='Monthly Cost'!$D$6+'Monthly Cost'!$D$7+'Monthly Cost'!$D$9+'Monthly Cost'!$D$10+'Monthly Cost'!$D$11+'Monthly Cost'!$D$12 | E5: =B5+C5+D5+A5*'Assumptions'!$B$42/1000*'Assumptions'!$B$43*'Assumptions'!$B$58 | F5: =A5*'Assumptions'!$B$47 | G5: =IF(F5=0,0,E5/F5)
A6: 20 | B6: =MAX('Assumptions'!$B$16*'Assumptions'!$B$19+A6*'Assumptions'!$B$7*'Assumptions'!$B$9*'Assumptions'!$B$13/1024*'Assumptions'!$B$20,'Assumptions'!$B$21)*'Assumptions'!$B$58 | C6: =A6*'Assumptions'!$B$47*'Assumptions'!$B$49+A6*'Assumptions'!$B$50 | D6: ='Monthly Cost'!$D$6+'Monthly Cost'!$D$7+'Monthly Cost'!$D$9+'Monthly Cost'!$D$10+'Monthly Cost'!$D$11+'Monthly Cost'!$D$12 | E6: =B6+C6+D6+A6*'Assumptions'!$B$42/1000*'Assumptions'!$B$43*'Assumptions'!$B$58 | F6: =A6*'Assumptions'!$B$47 | G6: =IF(F6=0,0,E6/F6)
A7: 30 | B7: =MAX('Assumptions'!$B$16*'Assumptions'!$B$19+A7*'Assumptions'!$B$7*'Assumptions'!$B$9*'Assumptions'!$B$13/1024*'Assumptions'!$B$20,'Assumptions'!$B$21)*'Assumptions'!$B$58 | C7: =A7*'Assumptions'!$B$47*'Assumptions'!$B$49+A7*'Assumptions'!$B$50 | D7: ='Monthly Cost'!$D$6+'Monthly Cost'!$D$7+'Monthly Cost'!$D$9+'Monthly Cost'!$D$10+'Monthly Cost'!$D$11+'Monthly Cost'!$D$12 | E7: =B7+C7+D7+A7*'Assumptions'!$B$42/1000*'Assumptions'!$B$43*'Assumptions'!$B$58 | F7: =A7*'Assumptions'!$B$47 | G7: =IF(F7=0,0,E7/F7)
A8: 50 | B8: =MAX('Assumptions'!$B$16*'Assumptions'!$B$19+A8*'Assumptions'!$B$7*'Assumptions'!$B$9*'Assumptions'!$B$13/1024*'Assumptions'!$B$20,'Assumptions'!$B$21)*'Assumptions'!$B$58 | C8: =A8*'Assumptions'!$B$47*'Assumptions'!$B$49+A8*'Assumptions'!$B$50 | D8: ='Monthly Cost'!$D$6+'Monthly Cost'!$D$7+'Monthly Cost'!$D$9+'Monthly Cost'!$D$10+'Monthly Cost'!$D$11+'Monthly Cost'!$D$12 | E8: =B8+C8+D8+A8*'Assumptions'!$B$42/1000*'Assumptions'!$B$43*'Assumptions'!$B$58 | F8: =A8*'Assumptions'!$B$47 | G8: =IF(F8=0,0,E8/F8)
A9: 100 | B9: =MAX('Assumptions'!$B$16*'Assumptions'!$B$19+A9*'Assumptions'!$B$7*'Assumptions'!$B$9*'Assumptions'!$B$13/1024*'Assumptions'!$B$20,'Assumptions'!$B$21)*'Assumptions'!$B$58 | C9: =A9*'Assumptions'!$B$47*'Assumptions'!$B$49+A9*'Assumptions'!$B$50 | D9: ='Monthly Cost'!$D$6+'Monthly Cost'!$D$7+'Monthly Cost'!$D$9+'Monthly Cost'!$D$10+'Monthly Cost'!$D$11+'Monthly Cost'!$D$12 | E9: =B9+C9+D9+A9*'Assumptions'!$B$42/1000*'Assumptions'!$B$43*'Assumptions'!$B$58 | F9: =A9*'Assumptions'!$B$47 | G9: =IF(F9=0,0,E9/F9)
A10: 200 | B10: =MAX('Assumptions'!$B$16*'Assumptions'!$B$19+A10*'Assumptions'!$B$7*'Assumptions'!$B$9*'Assumptions'!$B$13/1024*'Assumptions'!$B$20,'Assumptions'!$B$21)*'Assumptions'!$B$58 | C10: =A10*'Assumptions'!$B$47*'Assumptions'!$B$49+A10*'Assumptions'!$B$50 | D10: ='Monthly Cost'!$D$6+'Monthly Cost'!$D$7+'Monthly Cost'!$D$9+'Monthly Cost'!$D$10+'Monthly Cost'!$D$11+'Monthly Cost'!$D$12 | E10: =B10+C10+D10+A10*'Assumptions'!$B$42/1000*'Assumptions'!$B$43*'Assumptions'!$B$58 | F10: =A10*'Assumptions'!$B$47 | G10: =IF(F10=0,0,E10/F10)
A11: 500 | B11: =MAX('Assumptions'!$B$16*'Assumptions'!$B$19+A11*'Assumptions'!$B$7*'Assumptions'!$B$9*'Assumptions'!$B$13/1024*'Assumptions'!$B$20,'Assumptions'!$B$21)*'Assumptions'!$B$58 | C11: =A11*'Assumptions'!$B$47*'Assumptions'!$B$49+A11*'Assumptions'!$B$50 | D11: ='Monthly Cost'!$D$6+'Monthly Cost'!$D$7+'Monthly Cost'!$D$9+'Monthly Cost'!$D$10+'Monthly Cost'!$D$11+'Monthly Cost'!$D$12 | E11: =B11+C11+D11+A11*'Assumptions'!$B$42/1000*'Assumptions'!$B$43*'Assumptions'!$B$58 | F11: =A11*'Assumptions'!$B$47 | G11: =IF(F11=0,0,E11/F11)
A13: Highlighted row is your stated case: 30 students/month.
A14: Infrastructure as a share of revenue FALLS as you grow: the fixed costs (hardware, internet, domain) spread over more students while only the gateway fee stays proportional.
A15: Formulas were checked cell-by-cell and cross-computed in Python, but NOT recalculated by a spreadsheet engine — no LibreOffice on the machine that built this. Open it once and confirm the totals.

Sheet Hosting Options
A1: Hosting: Mac mini vs the alternatives
A2: Cost is not what decides this. Uptime is.
A4: Option | B4: IDR / month | C4: Setup effort | D4: What you are actually trading
A5: Mac mini (self-hosted) | B5: ='Monthly Cost'!D9+'Monthly Cost'!D10+'Monthly Cost'!D11 | C5: Already done | D5: Cheapest, full control. You own uptime: home power cuts, ISP outages, and your own reboots are now product incidents.
A6: Small cloud VPS | B6: =350000 | C6: Half a day | D6: 4 vCPU / 8 GB in Singapore. Datacentre power and network, snapshots, static IP. You still patch the OS.
A7: Managed container host | B7: =800000 | C7: A day | D7: Deploys from git, restarts on crash, managed Postgres available. Least operational burden, highest bill.
A9: The risk that actually matters for THIS product
A10: The final assessment is a 115-minute timed exam with a SERVER-AUTHORITATIVE clock. If the Mac mini or your home internet drops mid-sitting, the learner's deadline keeps advancing in wall-clock time while they cannot reach the app. They can lose a paid attempt through no fault of their own, and you will be issuing manual retakes and refunds. That is a support and reputation cost no hosting line item captures.
A12: Reasonable position
A13: Mac mini is fine for building, piloting, and a first small cohort. Move to a datacentre before you run exams you would have to refund. The app is already containerised and tunnel-fronted, so the move is a compose file and a DNS change, not a rewrite.
